Workbook
Name AG: #REF!
Name AG: #REF!
Name GA: #REF!
Name GA: #REF!
Name SegmentaciónDeDatos_DEPARTAMENTO: #REF!
Name SegmentaciónDeDatos_SEDE: #REF!

Sheet CheckList
D11: FORMATO | O11: Código:
D12: ACTA DE ENTREGA DE EQUIPO | O12: Fecha:
O13: Versión: 001
C15: Item | D15: 11
C16: Empresa | D16: =IFERROR(VLOOKUP($D$15,'Inventario TI'!A4:EE438,2,FALSE),"NA") -> AGENCIA MARITIMA KENRICK S.A.
C17: Código (DNI) | D17: =IFERROR(VLOOKUP($D$15,'Inventario TI'!A4:EE438,3,FALSE),"NA") -> 74964897
C18: Usuario (Apellidos y Nombres) | D18: =IFERROR(CONCATENATE(VLOOKUP($D$15,'Inventario TI'!A4:EE438,5,FALSE),", ",VLOOKUP($D$15,'Inventario TI'!A4:EE438,4,FALSE)),"NA") -> VALENCIA LEON, EVA BRUNELLA | K18: Tipo de asignación | L18: =IFERROR(VLOOKUP($D$15,'Inventario TI'!A4:EE438,10,FALSE),"NA") -> REEMPLAZO
C19: Sede | D19: =IFERROR(VLOOKUP($D$15,'Inventario TI'!A4:EE438,6,FALSE),"NA") -> SAN ISIDRO | K19: Otros Comentarios | L19: =IFERROR(VLOOKUP($D$15,'Inventario TI'!$A$4:$EE$438,66,FALSE),"NA") -> CAMBIO DE LAPTOP + ACCESORIOS
C20: Área | D20: =IFERROR(VLOOKUP($D$15,'Inventario TI'!A4:EE438,7,FALSE),"NA") -> REPRESENTACIONES Y BACKOFFICE
C21: Puesto | D21: =IFERROR(VLOOKUP($D$15,'Inventario TI'!A4:EE438,8,FALSE),"NA") -> PRACTICANTE
C24: Por el presente tomo conocimiento de las políticas de uso de los activos de cómputo de TRANSTOTAL AGENCIA MARITIMA S.A y me comprometo a respetarlas bajo responsabilidad personal: 1. Declaro y estoy de acuerdo en recibir los equipos con las siguientes características:
C30: =IFERROR(VLOOKUP($D$15,'Inventario TI'!A4:EE438,9,FALSE),"NA") -> LAPTOP | I30: MONITOR | N30: =IFERROR(VLOOKUP($D$15,'Inventario TI'!$A$4:$EE$438,45,FALSE),"NA") -> NA
C31: Marca: | D31: =IFERROR(VLOOKUP($D$15,'Inventario TI'!A4:EE438,13,FALSE),"NA") -> HP | I31: Marca: | K31: =IFERROR(VLOOKUP($D$15,'Inventario TI'!$A$4:$EE$438,29,FALSE),"NA") -> LENOVO | N31: Marca: | O31: =IFERROR(VLOOKUP($D$15,'Inventario TI'!$A$4:$EE$438,46,FALSE),"NA") -> NA
C32: Modelo: | D32: =IFERROR(VLOOKUP($D$15,'Inventario TI'!A4:EE438,14,FALSE),"NA") -> Probook 440 15 | I32: Modelo: | K32: =IFERROR(VLOOKUP($D$15,'Inventario TI'!$A$4:$EE$438,30,FALSE),"NA") -> THINKVISION E24-30 FLAT | N32: Modelo: | O32: =IFERROR(VLOOKUP($D$15,'Inventario TI'!$A$4:$EE$438,47,FALSE),"NA") -> NA
C33: Nro. Serie: | D33: =IFERROR(VLOOKUP($D$15,'Inventario TI'!A4:EE438,15,FALSE),"NA") -> 5CD5401LVT | I33: Serie: | K33: =IFERROR(VLOOKUP($D$15,'Inventario TI'!$A$4:$EE$438,31,FALSE),"NA") -> VNABG09Z | N33: Serie: | O33: =IFERROR(VLOOKUP($D$15,'Inventario TI'!$A$4:$EE$438,48,FALSE),"NA") -> NA
C34: Hostname: | D34: =IFERROR(VLOOKUP($D$15,'Inventario TI'!A4:EE438,11,FALSE),"NA") -> PETAMLT0057 | I34: Codigo Interno: | K34: =IFERROR(VLOOKUP($D$15,'Inventario TI'!$A$4:$EE$438,32,FALSE),"NA") -> TAM-AF0056 | N34: Codigo Interno: | O34: =IFERROR(VLOOKUP($D$15,'Inventario TI'!$A$4:$EE$438,49,FALSE),"NA") -> NA
C35: Codigo Interno: | D35: =IFERROR(VLOOKUP($D$15,'Inventario TI'!A5:EE439,12,FALSE),"NA") -> NA
I36: MOCHILA | N36: =IFERROR(VLOOKUP($D$15,'Inventario TI'!$A$4:$EE$438,50,FALSE),"NA") -> NA
C37: CARGADOR DE LAPTOP | I37: Marca: | K37: =IFERROR(VLOOKUP($D$15,'Inventario TI'!$A$4:$EE$438,33,FALSE),"NA") -> HP | N37: Marca: | O37: =IFERROR(VLOOKUP($D$15,'Inventario TI'!$A$4:$EE$438,51,FALSE),"NA") -> NA
C38: Marca: | D38: =IFERROR(VLOOKUP($D$15,'Inventario TI'!A4:EE438,19,FALSE),"NA") -> HP | I38: Modelo: | K38: =IFERROR(VLOOKUP($D$15,'Inventario TI'!$A$4:$EE$438,34,FALSE),"NA") -> 6B8U6AA | N38: Modelo: | O38: =IFERROR(VLOOKUP($D$15,'Inventario TI'!$A$4:$EE$438,52,FALSE),"NA") -> NA
C39: Modelo: | D39: =IFERROR(VLOOKUP($D$15,'Inventario TI'!A4:EE438,20,FALSE),"NA") -> TPN-DA15 | I39: Serie: | K39: =IFERROR(VLOOKUP($D$15,'Inventario TI'!$A$4:$EE$438,35,FALSE),"NA") -> NA | N39: Serie: | O39: =IFERROR(VLOOKUP($D$15,'Inventario TI'!$A$4:$EE$438,53,FALSE),"NA") -> NA
C40: Nro. Serie: | D40: =IFERROR(VLOOKUP($D$15,'Inventario TI'!A4:EE438,21,FALSE),"NA") -> WHRCU0EARLHI4O | I40: Codigo Interno: | K40: =IFERROR(VLOOKUP($D$15,'Inventario TI'!$A$4:$EE$438,36,FALSE),"NA") -> NA | N40: Codigo Interno: | O40: =IFERROR(VLOOKUP($D$15,'Inventario TI'!$A$4:$EE$438,54,FALSE),"NA") -> NA
C42: TECLADO | I42: HEADSETS | N42: =IFERROR(VLOOKUP($D$15,'Inventario TI'!$A$4:$EE$438,55,FALSE),"NA") -> NA
C43: Marca: | D43: =IFERROR(VLOOKUP($D$15,'Inventario TI'!$A$4:$EE$438,22,FALSE),"NA") -> HP | I43: Marca: | K43: =IFERROR(VLOOKUP($D$15,'Inventario TI'!$A$4:$EE$438,37,FALSE),"NA") -> HP | N43: Marca: | O43: =IFERROR(VLOOKUP($D$15,'Inventario TI'!$A$4:$EE$438,56,FALSE),"NA") -> NA
C44: Modelo: | D44: =IFERROR(VLOOKUP($D$15,'Inventario TI'!A4:EE438,23,FALSE),"NA") -> HSA-A005K | I44: Modelo: | K44: =IFERROR(VLOOKUP($D$15,'Inventario TI'!$A$4:$EE$438,38,FALSE),"NA") -> TPA-A001H | N44: Modelo: | O44: =IFERROR(VLOOKUP($D$15,'Inventario TI'!$A$4:$EE$438,57,FALSE),"NA") -> NA
C45: Nro. Serie: | D45: =IFERROR(VLOOKUP($D$15,'Inventario TI'!A4:EE438,24,FALSE),"NA") -> 7CH5281DSP | I45: Serie: | K45: =IFERROR(VLOOKUP($D$15,'Inventario TI'!$A$4:$EE$438,39,FALSE),"NA") -> 7CH4290GKS | N45: Serie: | O45: =IFERROR(VLOOKUP($D$15,'Inventario TI'!$A$4:$EE$438,58,FALSE),"NA") -> NA
C46: Codigo Interno: | D46: =IFERROR(VLOOKUP($D$15,'Inventario TI'!A4:EE438,25,FALSE),"NA") -> NA | I46: Codigo Interno: | K46: =IFERROR(VLOOKUP($D$15,'Inventario TI'!$A$4:$EE$438,40,FALSE),"NA") -> NA | N46: Codigo Interno: | O46: =IFERROR(VLOOKUP($D$15,'Inventario TI'!$A$4:$EE$438,59,FALSE),"NA") -> NA
C48: MOUSE | I48: DOCKING STATION | N48: =IFERROR(VLOOKUP($D$15,'Inventario TI'!$A$4:$EE$438,60,FALSE),"NA") -> NA
C49: Marca: | D49: =IFERROR(VLOOKUP($D$15,'Inventario TI'!A4:EE438,26,FALSE),"NA") -> HP | I49: Marca: | K49: =IFERROR(VLOOKUP($D$15,'Inventario TI'!$A$4:$EE$438,41,FALSE),"NA") -> NA | N49: Marca: | O49: =IFERROR(VLOOKUP($D$15,'Inventario TI'!$A$4:$EE$438,61,FALSE),"NA") -> NA
C50: Modelo: | D50: =IFERROR(VLOOKUP($D$15,'Inventario TI'!$A$4:$EE$438,27,FALSE),"NA") -> HSA-A011M | I50: Modelo: | K50: =IFERROR(VLOOKUP($D$15,'Inventario TI'!$A$4:$EE$438,42,FALSE),"NA") -> NA | N50: Modelo: | O50: =IFERROR(VLOOKUP($D$15,'Inventario TI'!$A$4:$EE$438,62,FALSE),"NA") -> NA
C51: Nro. Serie: | D51: =IFERROR(VLOOKUP($D$15,'Inventario TI'!$A$4:$EE$438,28,FALSE),"NA") -> 7CH5281DSP | I51: Serie: | K51: =IFERROR(VLOOKUP($D$15,'Inventario TI'!$A$4:$EE$438,43,FALSE),"NA") -> NA | N51: Serie: | O51: =IFERROR(VLOOKUP($D$15,'Inventario TI'!$A$4:$EE$438,63,FALSE),"NA") -> NA
I52: Codigo Interno: | K52: =IFERROR(VLOOKUP($D$15,'Inventario TI'!$A$4:$EE$438,44,FALSE),"NA") -> NA | N52: Codigo Interno: | O52: =IFERROR(VLOOKUP($D$15,'Inventario TI'!$A$4:$EE$438,64,FALSE),"NA") -> NA
C59: 2. Hacer uso responsable del equipo, siguiendo las políticas de uso y cuidado establecidas por la empresa y detalladas en el presente documento.
C61: 3. Cuidar la laptop contra daño, y reportar inmediatamente cualquier incidente al área de TI en caso de pérdida o robo.
C63: 4. No instalar software no autorizado o realizar modificaciones no permitidas al sistema.
C65: 5. Permitir revisiones, auditorías y mantenimiento cuando la empresa lo solicite.
C67: 6. Devolver el equipo en buen estado cuando sea requerido por la empresa o al finalizar la relación laboral.
C69: 7. Acatar las políticas de descuento, en caso sea aplicable.
N73: Lima; | O73: =TODAY() -> 46013
C78: Area TI | G78: Entregado por: | L78: Usuario
...

Sheet Inventario TI
A2: 1 | B2: 2 | C2: 3 | D2: 4 | E2: 5 | F2: 6 | G2: 7 | H2: 8 | I2: 9 | J2: 10 | K2: 11 | L2: 12 | M2: 13 | N2: 14 | O2: 15 | P2: 16 | Q2: 17 | R2: 18 | S2: 19 | T2: 20 | U2: 21 | V2: 22 | W2: 23 | X2: 24 | Y2: 25 | Z2: 26 | AA2: 27 | AB2: 28 | AC2: 29 | AD2: 30 | AE2: 31 | AF2: 32 | AG2: 33 | AH2: 34 | AI2: 35 | AJ2: 36 | AK2: 37 | AL2: 38 | AM2: 39 | AN2: 40 | AO2: 41 | AP2: 42 | AQ2: 43 | AR2: 44 | AS2: 45 | AT2: 46 | AU2: 47 | AV2: 48 | AW2: 49 | AX2: 50 | AY2: 51 | AZ2: 52 | BA2: 53 | BB2: 54 | BC2: 55 | BD2: 56 | BE2: 57 | BF2: 58 | BG2: 59 | BH2: 60 | BI2: 61 | BJ2: 62 | BK2: 63 | BL2: 64 | BM2: 65 | BN2: 66 | BO2: 67 | BP2: 68 | BQ2: 69 | BR2: 70 | BS2: 71 | BT2: 72 | BU2: 73 | BV2: 74 | BW2: 75 | BX2: 76 | BY2: 77 | BZ2: 78 | CA2: 79 | CB2: 80 | CC2: 81 | CD2: 82 | CE2: 83 | CF2: 84 | CG2: 85 | CH2: 86 | CI2: 87 | CJ2: 88 | CK2: 89 | CL2: 90 | CM2: 91 | CN2: 92 | CO2: 93 | CP2: 94 | CQ2: 95 | CR2: 96 | CS2: 97 | CT2: 98 | CU2: 99 | CV2: 100 | CW2: 101 | CX2: 102 | CY2: 103 | CZ2: 104 | DA2: 105 | DB2: 106 | DC2: 107 | DD2: 108 | DE2: 109 | DF2: 110 | DG2: 111 | DH2: 112 | DI2: 113 | DJ2: 114 | DK2: 115
A3: DATOS DEL USUARIO | I3: DATOS DEL EQUIPO | S3: CARGADOR | V3: TECLADO | Z3: MOUSE | AC3: MONITOR | AG3: MOCHILA | AK3: HEADSETS | AO3: DOCKING STATION | AS3: OTROS ACCESORIOS | BM3: OTROS COMPLEMENTOS
A4: ITEM | B4: EMPRESA | C4: DNI | D4: NOMBRES | E4: APELLIDOS | F4: SEDE | G4: AREA | H4: PUESTO | I4: TIPO DE EQUIPO | J4: TIPO DE ENTREGA | K4: NOMBRE DEL EQUIPO | L4: CODIGO INTERNO | M4: MARCA | N4: MODELO | O4: SERIE | P4: PROCESADOR | Q4: DISCO | R4: RAM | S4: MARCA | T4: MODELO | U4: SERIE | V4: MARCA | W4: MODELO | X4: SERIE | Y4: CODIGO INTERNO | Z4: MARCA | AA4: MODELO | AB4: SERIE | AC4: MARCA | AD4: MODELO | AE4: SERIE | AF4: CODIGO INTERNO | AG4: MARCA | AH4: MODELO | AI4: SERIE | AJ4: CODIGO INTERNO | AK4: MARCA | AL4: MODELO | AM4: SERIE | AN4: CODIGO INTERNO | AO4: MARCA | AP4: MODELO | AQ4: SERIE | AR4: CODIGO INTERNO | AS4: TIPO | AT4: MARCA | AU4: MODELO | AV4: SERIE | AW4: CODIGO INTERNO | AX4: TIPO | AY4: MARCA | AZ4: MODELO | BA4: SERIE | BB4: CODIGO INTERNO | BC4: TIPO | BD4: MARCA | BE4: MODELO | BF4: SERIE | BG4: CODIGO INTERNO | BH4: TIPO | BI4: MARCA | BJ4: MODELO | BK4: SERIE | BL4: CODIGO INTERNO | BM4: TI QUE ASIGNA | BN4: OTROS COMENTARIOS
A5: 1 | B5: TRANSTOTAL AGENCIA MARITIMA S.A | C5: 46386653 | D5: SINDY LIZETH | E5: PACHAS HERRERA | F5: SAN ISIDRO | G5: CONTABILIDAD | H5: ANALISTA CONTABLE | I5: LAPTOP | J5: REEMPLAZO | K5: PETAMLT0039 | L5: NA | M5: HP | N5: Probook 440 14 | O5: 5CD5401LWS | P5: I7 155U | Q5: 1 TB (SSD) | R5: 16 GB | S5: HP | T5: TPN-CA20 | U5: WTYLE0A3JL0AJO | V5: HP | W5: HSA-A005K | X5: 7CH5281DSL | Y5: NA | Z5: HP | AA5: HSA-A011M | AB5: 7CH5281DSL | AC5: NA | AD5: NA | AE5: NA | AF5: NA | AG5: HP | AH5: 6B8U6AA | AI5: NA | AJ5: NA | AK5: HP | AL5: TPA-A001H | AM5: 7CH4290FLH | AN5: NA | AO5: NA | AP5: NA | AQ5: NA | AR5: NA | AS5: MOUSEPAD | AT5: HP | AU5: NA | AV5: NA | AW5: NA | AX5: NA | AY5: NA | AZ5: NA | BA5: NA | BB5: NA | BC5: NA | BD5: NA | BE5: NA | BF5: NA | BG5: NA | BH5: NA | BI5: NA | BJ5: NA | BK5: NA | BL5: NA | BM5: GILMAR PEREZ | BN5: CAMBIO DE LAPTOP + ACCESORIOS
A6: 2 | B6: TRANSTOTAL AGENCIA MARITIMA S.A | C6: 45133198 | D6: JANETH | E6: NONAJULCA GARROTE | F6: SAN ISIDRO | G6: CONTABILIDAD | H6: JEFE DE CONTABILIDAD | I6: LAPTOP | J6: REEMPLAZO | K6: PETAMLT0053 | L6: NA | M6: HP | N6: Probook 440 14 | O6: 5CD5401LXQ | P6: I7 155U | Q6: 1 TB (SSD) | R6: 16 GB | S6: HP | T6: TPN-DA15 | U6: WHRCU0EARLHI65 | V6: HP | W6: HSA-A005K | X6: 7CH5281DSJ | Y6: NA | Z6: HP | AA6: HSA-A011M | AB6: 7CH5281DSJ | AC6: NA | AD6: NA | AE6: NA | AF6: NA | AG6: HP | AH6: 6B8U6AA | AI6: NA | AJ6: NA | AK6: HP | AL6: TPA-A001H | AM6: 7CH4290FLC | AN6: NA | AO6: NA | AP6: NA | AQ6: NA | AR6: NA | AS6: MOUSEPAD | AT6: HP | AU6: NA | AV6: NA | AW6: NA | AX6: NA | AY6: NA | AZ6: NA | BA6: NA | BB6: NA | BC6: NA | BD6: NA | BE6: NA | BF6: NA | BG6: NA | BH6: NA | BI6: NA | BJ6: NA | BK6: NA | BL6: NA | BM6: GILMAR PEREZ | BN6: CAMBIO DE LAPTOP + ACCESORIOS
A7: 3 | B7: TRANSTOTAL AGENCIA MARITIMA S.A | C7: 46798117 | D7: TATIANA ARACELI | E7: AYALA HIGINIO | F7: SAN ISIDRO | G7: REPRESENTACIONES Y BACK OFFICE | H7: ASISTENTE DE FINANZAS LINEAS | I7: LAPTOP | J7: REEMPLAZO | K7: PETAMLT0058 | L7: NA | M7: HP | N7: Probook 440 14 | O7: 1H85341SSQ | P7: I7 155U | Q7: 1 TB (SSD) | R7: 16 GB | S7: HP | T7: TPN-CA20 | U7: WTYLE0A3JKW38J | V7: HP | W7: HSA-A005K | X7: 7CH5281DSK | Y7: NA | Z7: HP | AA7: HSA-A011M | AB7: 7CH5281DSK | AC7: LENOVO | AD7: THINKVISION E24-30 FLAT | AE7: VNABG0AY | AF7: TAM-AF0068 | AG7: HP | AH7: 6B8U6AA | AI7: NA | AJ7: NA | AK7: HP | AL7: TPA-A001H | AM7: 7CH4290FLG | AN7: NA | AO7: NA | AP7: NA | AQ7: NA | AR7: NA | AS7: NA | AT7: NA | AU7: NA | AV7: NA | AW7: NA | AX7: NA | AY7: NA | AZ7: NA | BA7: NA | BB7: NA | BC7: NA | BD7: NA | BE7: NA | BF7: NA | BG7: NA | BH7: NA | BI7: NA | BJ7: NA | BK7: NA | BL7: NA | BM7: JAMMES ARELLANO | BN7: CAMBIO DE LAPTOP + ACCESORIOS
A8: 4 | B8: TRANSTOTAL AGENCIA MARITIMA S.A | C8: 72871476 | D8: MIRELLA LESLY | E8: YATACO TASAYCO | F8: SAN ISIDRO | G8: REPRESENTACIONES Y BACK OFFICE | H8: SUPERVISOR DE GLOBALDESK | I8: LAPTOP | J8: REEMPLAZO | K8: PETAMLT0054 | L8: NA | M8: HP | N8: Probook 440 14 | O8: 1H85341ST1 | P8: I7 155U | Q8: 1 TB (SSD) | R8: 16 GB | S8: HP | T8: TPN-DA15 | U8: WHRCU0EARLHI4N | V8: HP | W8: HSA-A005K | X8: 7CH5281DSH | Y8: NA | Z8: HP | AA8: HSA-A011M | AB8: 7CH5281DSH | AC8: NA | AD8: NA | AE8: NA | AF8: NA | AG8: HP | AH8: 6B8U6AA | AI8: NA | AJ8: NA | AK8: HP | AL8: TPA-A001H | AM8: 7CH4290FLD | AN8: NA | AO8: NA | AP8: NA | AQ8: NA | AR8: NA | AS8: MOUSEPAD | AT8: HP | AU8: NA | AV8: NA | AW8: NA | AX8: NA | AY8: NA | AZ8: NA | BA8: NA | BB8: NA | BC8: NA | BD8: NA | BE8: NA | BF8: NA | BG8: NA | BH8: NA | BI8: NA | BJ8: NA | BK8: NA | BL8: NA | BM8: GILMAR PEREZ | BN8: CAMBIO DE LAPTOP + ACCESORIOS
A9: 5 | B9: TRANSTOTAL AGENCIA MARITIMA S.A | C9: 41654840 | D9: FEDRA MILYA | E9: MILLA GARGATE | F9: SAN ISIDRO | G9: REPRESENTACIONES Y BACK OFFICE | H9: AUXILIAR DE GESTION Y CONTROL | I9: LAPTOP | J9: REEMPLAZO | K9: PETAMLT0043 | L9: NA | M9: HP | N9: Probook 440 14 | O9: S5CD5401LWH | P9: I7 155U | Q9: 1 TB (SSD) | R9: 16 GB | S9: HP | T9: TPN-DA15 | U9: WHRCU0EARLHLEL | V9: HP | W9: HSA-A005K | X9: 7CH5163FGS | Y9: NA | Z9: HP | AA9: HSA-A011M | AB9: 7CH5163FGS | AC9: LENOVO | AD9: THINKVISION E24-30 FLAT | AE9: VNABG095 | AF9: TAM-AF0067 | AG9: HP | AH9: 6B8U6AA | AI9: NA | AJ9: NA | AK9: HP | AL9: TPA-A001H | AM9: 7CH4290GKM | AN9: NA | AO9: NA | AP9: NA | AQ9: NA | AR9: NA | AS9: MOUSEPAD | AT9: HP | AU9: NA | AV9: NA | AW9: NA | AX9: NA | AY9: NA | AZ9: NA | BA9: NA | BB9: NA | BC9: NA | BD9: NA | BE9: NA | BF9: NA | BG9: NA | BH9: NA | BI9: NA | BJ9: NA | BK9: NA | BL9: NA | BM9: JAMMES ARELLANO | BN9: CAMBIO DE LAPTOP + ACCESORIOS
A10: 6 | B10: TRANSTOTAL AGENCIA MARITIMA S.A | C10: 74762209 | D10: DIANA LIZ | E10: VASQUEZ VALERIO | F10: SAN ISIDRO | G10: REPRESENTACIONES Y BACK OFFICE | H10: ASISTENTE DE GESTION Y CONTROL | I10: LAPTOP | J10: REEMPLAZO | K10: PETAMLT0044 | L10: NA | M10: HP | N10: Probook 440 14 | O10: 5CD5401LX9 | P10: I7 155U | Q10: 1 TB (SSD) | R10: 16 GB | S10: HP | T10: TPN-DA15 | U10: WHRCU0EARLHI4P | V10: HP | W10: HSA-A005K | X10: 7CH5163FGR | Y10: NA | Z10: HP | AA10: HSA-A011M | AB10: 7CH5163FGR | AC10: NA | AD10: NA | AE10: NA | AF10: NA | AG10: HP | AH10: 6B8U6AA | AI10: NA | AJ10: NA | AK10: HP | AL10: TPA-A001H | AM10: 7CH4290FLB | AN10: NA | AO10: NA | AP10: NA | AQ10: NA | AR10: NA | AS10: NA | AT10: NA | AU10: NA | AV10: NA | AW10: NA | AX10: NA | AY10: NA | AZ10: NA | BA10: NA | BB10: NA | BC10: NA | BD10: NA | BE10: NA | BF10: NA | BG10: NA | BH10: NA | BI10: NA | BJ10: NA | BK10: NA | BL10: NA | BM10: GILMAR PEREZ | BN10: CAMBIO DE LAPTOP + ACCESORIOS
A11: 7 | B11: TRANSTOTAL AGENCIA MARITIMA S.A | C11: 72180497 | D11: DARYEN FOSTER | E11: LAZARO PARDO | F11: SAN ISIDRO | G11: REPRESENTACIONES Y BACK OFFICE | H11: AUXILIAR DE USER EXPERIENCE | I11: LAPTOP | J11: REEMPLAZO | K11: PETAMLT0035 | L11: NA | M11: HP | N11: Probook 440 14 | O11: 5CD5401LYT | P11: I7 155U | Q11: 1 TB (SSD) | R11: 16 GB | S11: HP | T11: TPN-DA15 | U11: WHRCU0EARLHLFK | V11: HP | W11: HSA-A005K | X11: 7CH5281DSF | Y11: NA | Z11: HP | AA11: HSA-A011M | AB11: 7CH5281DSF | AC11: LENOVO | AD11: THINKVISION E24-30 FLAT | AE11: VNABG0A8 | AF11: NA | AG11: HP | AH11: 6B8U6AA | AI11: NA | AJ11: NA | AK11: HP | AL11: TPA-A001H | AM11: 7CH4290FL9 | AN11: NA | AO11: NA | AP11: NA | AQ11: NA | AR11: NA | AS11: MOUSEPAD | AT11: HP | AU11: NA | AV11: NA | AW11: NA | AX11: NA | AY11: NA | AZ11: NA | BA11: NA | BB11: NA | BC11: NA | BD11: NA | BE11: NA | BF11: NA | BG11: NA | BH11: NA | BI11: NA | BJ11: NA | BK11: NA | BL11: NA | BM11: JAMMES ARELLANO | BN11: CAMBIO DE LAPTOP + ACCESORIOS
A12: 8 | B12: AGENCIA MARITIMA KENRICK S.A. | C12: 76791427 | D12: LUGIUI YORDAN | E12: UGAZ NORIEGA | F12: SAN ISIDRO | G12: REPRESENTACIONES Y BACKOFFICE | H12: CUSTOMER SERVICE | I12: LAPTOP | J12: REEMPLAZO | K12: PETAMLT0060 | L12: NA | M12: HP | N12: Probook 440 14 | O12: 5CD54105ZW | P12: I7 155U | Q12: 1 TB (SSD) | R12: 16 GB | S12: HP | T12: TPN-DA15 | U12: WHRCU0EARLHLEE | V12: HP | W12: HSA-A005K | X12: 7CH5281DSM | Y12: NA | Z12: HP | AA12: HSA-A011M | AB12: 7CH5281DSM | AC12: NA | AD12: NA | AE12: NA | AF12: NA | AG12: HP | AH12: 6B8U6AA | AI12: NA | AJ12: NA | AK12: HP | AL12: TPA-A001H | AM12: 7CH4290H6M | AN12: NA | AO12: NA | AP12: NA | AQ12: NA | AR12: NA | AS12: NA | AT12: NA | AU12: NA | AV12: NA | AW12: NA | AX12: NA | AY12: NA | AZ12: NA | BA12: NA | BB12: NA | BC12: NA | BD12: NA | BE12: NA | BF12: NA | BG12: NA | BH12: NA | BI12: NA | BJ12: NA | BK12: NA | BL12: NA | BM12: GILMAR PEREZ | BN12: CAMBIO DE LAPTOP + ACCESORIOS
A13: 9 | B13: ULOG PERU S.A. | C13: 76589058 | D13: GABRIEL HANS | E13: WAGNER URIBE | F13: SAN ISIDRO | G13: ULOG | H13: PRACTICANTE | I13: LAPTOP | J13: REEMPLAZO | K13: PETAMLT0036 | L13: NA | M13: HP | N13: Probook 440 15 | O13: 5CD5401LXY | P13: I7 155U | Q13: 1 TB (SSD) | R13: 16 GB | S13: HP | T13: TPN-DA15 | U13: WHRRF0A3ULFGN9 | V13: HP | W13: HSA-A005K | X13: 7CH5281DSN | Y13: NA | Z13: HP | AA13: HSA-A011M | AB13: 7CH5281DSN | AC13: LENOVO | AD13: THINKVISION E24-30 FLAT | AE13: VNABG08N | AF13: TAM-AF0105 | AG13: HP | AH13: 6B8U6AA | AI13: NA | AJ13: NA | AK13: HP | AL13: TPA-A001H | AM13: 7CH4290FLQ | AN13: NA | AO13: NA | AP13: NA | AQ13: NA | AR13: NA | AS13: NA | AT13: NA | AU13: NA | AV13: NA | AW13: NA | AX13: NA | AY13: NA | AZ13: NA | BA13: NA | BB13: NA | BC13: NA | BD13: NA | BE13: NA | BF13: NA | BG13: NA | BH13: NA | BI13: NA | BJ13: NA | BK13: NA | BL13: NA | BM13: GILMAR PEREZ | BN13: CAMBIO DE LAPTOP + ACCESORIOS
A14: 10 | B14: AGENCIA MARITIMA KENRICK S.A. | C14: 75591310 | D14: NAYDELINE INES ARIANA | E14: MARCHENA CHAVEZ | F14: SAN ISIDRO | G14: REPRESENTACIONES Y BACKOFFICE | H14: CUSTOMER SERVICE JUNIOR | I14: LAPTOP | J14: REEMPLAZO | K14: PETAMLT0034 | L14: NA | M14: HP | N14: Probook 440 15 | O14: 5CD5401LXP | P14: I7 155U | Q14: 1 TB (SSD) | R14: 16 GB | S14: HP | T14: TPN-DA15 | U14: WHRCU0EARLHI4J | V14: HP | W14: HSA-A005K | X14: 7CH5163FGQ | Y14: NA | Z14: HP | AA14: HSA-A011M | AB14: 7CH5163FGQ | AC14: LENOVO | AD14: THINKVISION E24-30 FLAT | AE14: VNABG09F | AF14: TAM-AF0055 | AG14: HP | AH14: 6B8U6AA | AI14: NA | AJ14: NA | AK14: HP | AL14: TPA-A001H | AM14: 7CH4290GKN | AN14: NA | AO14: NA | AP14: NA | AQ14: NA | AR14: NA | AS14: NA | AT14: NA | AU14: NA | AV14: NA | AW14: NA | AX14: NA | AY14: NA | AZ14: NA | BA14: NA | BB14: NA | BC14: NA | BD14: NA | BE14: NA | BF14: NA | BG14: NA | BH14: NA | BI14: NA | BJ14: NA | BK14: NA | BL14: NA | BM14: JAMMES ARELLANO | BN14: CAMBIO DE LAPTOP + ACCESORIOS
A15: 11 | B15: AGENCIA MARITIMA KENRICK S.A. | C15: 74964897 | D15: EVA BRUNELLA | E15: VALENCIA LEON | F15: SAN ISIDRO | G15: REPRESENTACIONES Y BACKOFFICE | H15: PRACTICANTE | I15: LAPTOP | J15: REEMPLAZO | K15: PETAMLT0057 | L15: NA | M15: HP | N15: Probook 440 15 | O15: 5CD5401LVT | P15: I7 155U | Q15: 1 TB (SSD) | R15: 16 GB | S15: HP | T15: TPN-DA15 | U15: WHRCU0EARLHI4O | V15: HP | W15: HSA-A005K | X15: 7CH5281DSP | Y15: NA | Z15: HP | AA15: HSA-A011M | AB15: 7CH5281DSP | AC15: LENOVO | AD15: THINKVISION E24-30 FLAT | AE15: VNABG09Z | AF15: TAM-AF0056 | AG15: HP | AH15: 6B8U6AA | AI15: NA | AJ15: NA | AK15: HP | AL15: TPA-A001H | AM15: 7CH4290GKS | AN15: NA | AO15: NA | AP15: NA | AQ15: NA | AR15: NA | AS15: NA | AT15: NA | AU15: NA | AV15: NA | AW15: NA | AX15: NA | AY15: NA | AZ15: NA | BA15: NA | BB15: NA | BC15: NA | BD15: NA | BE15: NA | BF15: NA | BG15: NA | BH15: NA | BI15: NA | BJ15: NA | BK15: NA | BL15: NA | BM15: JAMMES ARELLANO | BN15: CAMBIO DE LAPTOP + ACCESORIOS
A16: 12 | B16: ULOG PERU S.A. | C16: 47326234 | D16: ARMANDO VLADIMIR | E16: CARDENAS CORREA | F16: SAN ISIDRO | G16: ULOG | H16: CUSTOMER SERVICE | I16: LAPTOP | J16: REEMPLAZO | K16: PETAMLT0059 | L16: NA | M16: HP | N16: Probook 440 15 | O16: 5CD5401LWT | P16: I7 155U | Q16: 1 TB (SSD) | R16: 16 GB | S16: HP | T16: TPN-DA15 | U16: WHRCU0EARLHLFO | V16: HP | W16: HSA-A005K | X16: 7CH5163FGT | Y16: NA | Z16: HP | AA16: HSA-A011M | AB16: 7CH5163FGT | AC16: LENOVO | AD16: THINKVISION E24-30 FLAT | AE16: VNABG0AR | AF16: TAM-AF0061 | AG16: HP | AH16: 6B8U6AA | AI16: NA | AJ16: NA | AK16: HP | AL16: TPA-A001H | AM16: 7CH4290FLP | AN16: NA | AO16: NA | AP16: NA | AQ16: NA | AR16: NA | AS16: NA | AT16: NA | AU16: NA | AV16: NA | AW16: NA | AX16: NA | AY16: NA | AZ16: NA | BA16: NA | BB16: NA | BC16: NA | BD16: NA | BE16: NA | BF16: NA | BG16: NA | BH16: NA | BI16: NA | BJ16: NA | BK16: NA | BL16: NA | BM16: GILMAR PEREZ | BN16: CAMBIO DE LAPTOP + ACCESORIOS
... A43: 39 | B43: TRANSTOTAL AGENCIA MARITIMA S.A | C43: 41350040 | D43: ROXANA FLOR | E43: CASTILLO VARGAS | F43: SAN ISIDRO | G43: CONTABILIDAD | H43: ANALISTA DE CONTABILIDAD | I43: LAPTOP | J43: REEMPLAZO | K43: PETAMLT0006 | L43: NA | M43: HP | N43: Probook 440 15 | O43: 5CD5401M2L | P43: I7 155U | Q43: 1 TB (SSD) | R43: 16 GB | S43: HP | T43: TPN-CA20 | U43: WTYLE0A3JL0GNK | V43: HP | W43: HSA-A005K | X43: 7CH5163BXJ | Y43: NA | Z43: HP | AA43: HSA-A011M | AB43: 7CH5163BXJ | AC43: LENOVO | AD43: THINKVISION E24-30 FLAT | AE43: VNABG0BB | AF43: TAM-AF0101 | AG43: HP | AH43: 6B8U6AA | AI43: NA | AJ43: NA | AK43: HP | AL43: TPA-A001H | AM43: 7CH4290FL1 | AN43: NA | AO43: NA | AP43: NA | AQ43: NA | AR43: NA | AS43: NA | AT43: NA | AU43: NA | AV43: NA | AW43: NA | AX43: NA | AY43: NA | AZ43: NA | BA43: NA | BB43: NA | BC43: NA | BD43: NA | BE43: NA | BF43: NA | BG43: NA | BH43: NA | BI43: NA | BJ43: NA | BK43: NA | BL43: NA | BM43: GILMAR PEREZ | BN43: ASIGNACION DE EQUIPO
A44: 40 | B44: TRANSTOTAL AGENCIA MARITIMA S.A | C44: 71625141 | D44: DARIANA JHULIE | E44: CARDENAS TAPARI | F44: SAN ISIDRO | G44: CONTABILIDAD | H44: PRACTICANTE DE CONTABILIDAD | I44: LAPTOP | J44: REEMPLAZO | K44: PETAMLT0001 | L44: NA | M44: HP | N44: Probook 440 15 | O44: 5CD5401LXS | P44: I7 155U | Q44: 1 TB (SSD) | R44: 16 GB | S44: HP | T44: TPN-DA15 | U44: WHRCU0EARLHI4I | V44: HP | W44: HSA-A005K | X44: 7CH5163BXD | Y44: NA | Z44: HP | AA44: HSA-A011M | AB44: 7CH5163BXD | AC44: LENOVO | AD44: THINKVISION E24-30 FLAT | AE44: VNABG080 | AF44: TAM-AF0103 | AG44: HP | AH44: 6B8U6AA | AI44: NA | AJ44: NA | AK44: HP | AL44: TPA-A001H | AN44: NA | AO44: NA | AP44: NA | AQ44: NA | AR44: NA | AS44: NA | AT44: NA | AU44: NA | AV44: NA | AW44: NA | AX44: NA | AY44: NA | AZ44: NA | BA44: NA | BB44: NA | BC44: NA | BD44: NA | BE44: NA | BF44: NA | BG44: NA | BH44: NA | BI44: NA | BJ44: NA | BK44: NA | BL44: NA | BM44: GILMAR PEREZ | BN44: ASIGNACION DE EQUIPO
A45: 41 | B45: TRANSTOTAL AGENCIA MARITIMA S.A | C45: 71693687 | D45: FABRIZZIO PAOLO | E45: CONCHA HERNANDEZ | F45: SAN ISIDRO | G45: TESORERIA | H45: PRACTICANTE DE ADMINISTRADCION Y TESORERIA | I45: LAPTOP | J45: REEMPLAZO | K45: PETAMLT0065 | L45: NA | M45: HP | N45: Probook 440 15 | O45: 5CD5401LZQ | P45: I7 155U | Q45: 1 TB (SSD) | R45: 16 GB | S45: HP | T45: TPN-DA15 | U45: WHRCU0EARLHI6F | V45: HP | W45: HSA-A005K | X45: 7CH5163BX4 | Y45: NA | Z45: HP | AA45: HSA-A011M | AB45: 7CH5163BX4 | AC45: LENOVO | AD45: THINKVISION E24-30 FLAT | AE45: VNABG0B9 | AF45: TAM-AF0087 | AG45: HP | AH45: 6B8U6AA | AI45: NA | AJ45: NA | AK45: HP | AL45: TPA-A001H | AM45: 7CH4290GL5 | AN45: NA | AO45: NA | AP45: NA | AQ45: NA | AR45: NA | AS45: NA | AT45: NA | AU45: NA | AV45: NA | AW45: NA | AX45: NA | AY45: NA | AZ45: NA | BA45: NA | BB45: NA | BC45: NA | BD45: NA | BE45: NA | BF45: NA | BG45: NA | BH45: NA | BI45: NA | BJ45: NA | BK45: NA | BL45: NA | BM45: GILMAR PEREZ | BN45: ASIGNACION DE EQUIPO
A46: 42 | B46: TRANSTOTAL AGENCIA MARITIMA S.A | C46: 74951459 | D46: STEFANNY LIZ | E46: POMACHAGUA YALI | F46: SAN ISIDRO | G46: TESORERIA | H46: ASISTENTE DE ADMINISTRACION | I46: LAPTOP | J46: REEMPLAZO | K46: PETAMLT0066 | L46: NA | M46: HP | N46: Probook 440 15 | O46: 5CD5401LXL | P46: I7 155U | Q46: 1 TB (SSD) | R46: 16 GB | S46: HP | T46: TPN-DA15 | U46: WHRCU0EARLHLE2 | V46: HP | W46: HSA-A005K | X46: 7CH5163BX5 | Y46: NA | Z46: HP | AA46: HSA-A011M | AB46: 7CH5163BX5 | AG46: HP | AH46: 6B8U6AA | AI46: NA | AJ46: NA | AK46: HP | AL46: TPA-A001H | AM46: 7CH4290GKP | AN46: NA | AO46: NA | AP46: NA | AQ46: NA | AR46: NA | AS46: NA | AT46: NA | AU46: NA | AV46: NA | AW46: NA | AX46: NA | AY46: NA | AZ46: NA | BA46: NA | BB46: NA | BC46: NA | BD46: NA | BE46: NA | BF46: NA | BG46: NA | BH46: NA | BI46: NA | BJ46: NA | BK46: NA | BL46: NA | BM46: GILMAR PEREZ | BN46: ASIGNACION DE EQUIPO
A47: 43 | B47: TRANSTOTAL AGENCIA MARITIMA S.A | C47: 44369362 | D47: JACKELINE FRANCESCA | E47: SUAREZ OBANDO | F47: SAN ISIDRO | G47: TESORERIA | H47: ASISTENTE DE TESORERIA | I47: LAPTOP | J47: REEMPLAZO | K47: PETAMLT0062 | L47: NA | M47: HP | N47: Probook 440 15 | O47: 5CD5401LZJ | P47: I7 155U | Q47: 1 TB (SSD) | R47: 16 GB | S47: HP | T47: TPN-DA15 | U47: WHRCU0EARLHI62 | V47: HP | W47: HSA-A005K | X47: 7CH5163BX3 | Y47: NA | Z47: HP | AA47: HSA-A011M | AB47: 7CH5163BX3 | AC47: LENOVO | AD47: THINKVISION E24-30 FLAT | AE47: VNABG0AZ | AF47: TAM-AF0086 | AG47: HP | AH47: 6B8U6AA | AI47: NA | AJ47: NA | AK47: HP | AL47: TPA-A001H | AM47: 7CH4290GL6 | AN47: NA | AO47: NA | AP47: NA | AQ47: NA | AR47: NA | AS47: NA | AT47: NA | AU47: NA | AV47: NA | AW47: NA | AX47: NA | AY47: NA | AZ47: NA | BA47: NA | BB47: NA | BC47: NA | BD47: NA | BE47: NA | BF47: NA | BG47: NA | BH47: NA | BI47: NA | BJ47: NA | BK47: NA | BL47: NA | BM47: GILMAR PEREZ | BN47: CAMBIO DE LAPTOP + ACCESORIOS
A48: 44 | B48: TRANSTOTAL AGENCIA MARITIMA S.A | C48: 44868360 | D48: LIZBETH ARACELI | E48: GUERRA SALCEDO | F48: SAN ISIDRO | G48: TESORERIA | H48: ANALISTA DE TESORERIA Y ADMINISTRACION | I48: LAPTOP | J48: REEMPLAZO | K48: PETAMLT0052 | L48: NA | M48: HP | N48: Probook 440 15 | P48: I7 155U | Q48: 1 TB (SSD) | R48: 16 GB | S48: HP | T48: TPN-DA15 | V48: HP | W48: HSA-A005K | Y48: NA | Z48: HP | AA48: HSA-A011M | AC48: LENOVO | AD48: THINKVISION E24-30 FLAT | AE48: VNABG09L | AF48: TAM-AF0085 | AG48: HP | AH48: 6B8U6AA | AI48: NA | AJ48: NA | AK48: HP | AL48: TPA-A001H | AN48: NA | AO48: NA | AP48: NA | AQ48: NA | AR48: NA | AS48: NA | AT48: NA | AU48: NA | AV48: NA | AW48: NA | AX48: NA | AY48: NA | AZ48: NA | BA48: NA | BB48: NA | BC48: NA | BD48: NA | BE48: NA | BF48: NA | BG48: NA | BH48: NA | BI48: NA | BJ48: NA | BK48: NA | BL48: NA | BM48: GILMAR PEREZ | BN48: CAMBIO DE LAPTOP + ACCESORIOS
A49: 45 | B49: TRANSTOTAL AGENCIA MARITIMA S.A | C49: 46142316 | D49: TESSY ESTEFANIE | E49: ARRUNATEGUI CASTRO | F49: SAN ISIDRO | G49: TESORERIA | H49: SUPERVISOR DE TESORERIA | I49: LAPTOP | J49: REEMPLAZO | K49: PETAMLT0008 | L49: NA | M49: HP | N49: Probook 440 15 | P49: I7 155U | Q49: 1 TB (SSD) | R49: 16 GB | S49: HP | T49: TPN-DA15 | U49: WHRCU0EARLHI6B | V49: HP | W49: HSA-A005K | X49: 7CH5163BX2 | Y49: NA | Z49: HP | AA49: HSA-A011M | AB49: 7CH5163BX2 | AC49: LENOVO | AD49: THINKVISION E24-30 FLAT | AE49: VNABG0A6 | AF49: TAM-AF0088 | AG49: HP | AH49: 6B8U6AA | AI49: NA | AJ49: NA | AK49: HP | AL49: TPA-A001H | AM49: 7CH4290GL3 | AN49: NA | AO49: NA | AP49: NA | AQ49: NA | AR49: NA | AS49: NA | AT49: NA | AU49: NA | AV49: NA | AW49: NA | AX49: NA | AY49: NA | AZ49: NA | BA49: NA | BB49: NA | BC49: NA | BD49: NA | BE49: NA | BF49: NA | BG49: NA | BH49: NA | BI49: NA | BJ49: NA | BK49: NA | BL49: NA | BM49: GILMAR PEREZ | BN49: CAMBIO DE LAPTOP + ACCESORIOS

Sheet BD PC
D2: Registro de equipos en stock
B3: Fecha de Actualización:
B4: Alcance:
C5: 1 | D5: 2 | E5: 3 | F5: 4 | G5: 5 | H5: 6 | I5: 7 | J5: 8 | K5: 9 | L5: 10 | M5: 11 | N5: 12 | O5: 13 | P5: 14 | Q5: 15 | R5: 16 | S5: 17 | T5: 18 | U5: 19 | V5: 20 | W5: 21 | X5: 22 | Y5: 23 | Z5: 24 | AA5: 25
B6: DATOS DEL USUARIO | C6: DATOS DEL EQUIPO INFORMÁTICO
B7: ITEM_REG | C7: ID EQUIPO | D7: TIPO EQUIPO | E7: HOSTNAME | F7: DOMINIO | G7: TIPO DE ASIGNACIÓN | H7: MARCA PC | I7: MODELO PC | J7: NRO. SERIE PC | K7: PROCESADOR PC | L7: PROCESADOR PC DESCRIPCIÓN | M7: DISCO DURO PC | N7: RAM PC | O7: CARGADOR PC (n/s) | P7: MAC LAN PC | Q7: MAC WIFI PC | R7: NRO. RQ PC | S7: FE INI GARANTIA PC | T7: FE FIN GARANTIA PC | U7: DIAS REST. GARANT. PC | V7: ESTADO GARANT. PC | W7: ESTADO PC | X7: NRO. FACTURA PC | Y7: ANTIGÜEDAD PC | Z7: NRO. CONTRATO PC | AA7: USUARIO ANTERIOR | AB7: PARA BAJA | AC7: PUESTO | AD7: FE_MOD_REG | AE7: COMENTARIO
C8: NA | D8: ANEXO | E8: NA | F8: NA | G8: NA | H8: GRANDSTREAM | I8: GXP1630 | J8: 20EZ0XUJ20D2B00F | K8: NA | L8: NA | M8: NA | N8: NA | O8: NA | P8: NA | Q8: NA | R8: NA | S8: NA | T8: NA | U8: =IFERROR(DATEDIF(TODAY(),T8,"D"),0) -> 0 | V8: =IF(U8=0,"SIN GARANTIA","CON GARANTIA") -> SIN GARANTIA | X8: =IFERROR(DATEDIF(R8,TODAY(),"Y"),"NA") -> NA | Y8: =IFERROR(DATEDIF(S8,TODAY(),"Y"),"NA") -> NA | Z8: NA | AB8: NA | AC8: JEFE LOGISTICA | AE8: 222
C9: NA | D9: ANEXO | E9: NA | F9: NA | G9: NA | H9: GRANDSTREAM | I9: GXP2130 | J9: 20EYZK0J70E268E3 | K9: NA | L9: NA | M9: NA | N9: NA | O9: NA | P9: NA | Q9: NA | R9: NA | S9: NA | T9: NA | U9: =IFERROR(DATEDIF(TODAY(),T9,"D"),0) -> 0 | V9: =IF(U9=0,"SIN GARANTIA","CON GARANTIA") -> SIN GARANTIA | X9: =IFERROR(DATEDIF(R9,TODAY(),"Y"),"NA") -> NA | Y9: =IFERROR(DATEDIF(S9,TODAY(),"Y"),"NA") -> NA | Z9: NA | AB9: NA | AC9: GERENTE COMERCIAL | AE9: 227
C10: NA | D10: ANEXO | E10: NA | F10: NA | G10: NA | H10: GRANDSTREAM | I10: GXP1628 | J10: 22MT9YDHA0C42DA7 | K10: NA | L10: NA | M10: NA | N10: NA | O10: NA | P10: NA | Q10: NA | R10: NA | S10: NA | T10: NA | U10: =IFERROR(DATEDIF(TODAY(),T10,"D"),0) -> 0 | V10: =IF(U10=0,"SIN GARANTIA","CON GARANTIA") -> SIN GARANTIA | X10: =IFERROR(DATEDIF(R10,TODAY(),"Y"),"NA") -> NA | Y10: =IFERROR(DATEDIF(S10,TODAY(),"Y"),"NA") -> NA | Z10: NA | AB10: NA | AC10: AREA TRAFICO | AE10: 215
B11: 101 | C11: NA | D11: LAPTOP | E11: CTL2020-014 | F11: HOLDING.COM | G11: PRINCIPAL | H11: LENOVO | I11: E590 | J11: PF2CY5AM | K11: INTEL CORE I7 8 GEN | L11: INTEL(R) CORE(TM) I7-8565U CPU @ 1.80GHZ (1992 MHZ) | M11: 500 GB (SSD) | N11: 16 GB | O11: ADLX65YCC2D | P11: 002B67AD502A | Q11: F8AC65FAF9D3 | R11: NA | S11: 44075 | T11: 45170 | U11: =IFERROR(DATEDIF(TODAY(),T11,"D"),0) -> 0 | V11: =IF(U11=0,"SIN GARANTIA","CON GARANTIA") -> SIN GARANTIA | W11: OPERATIVO | X11: FAFF01-00002208 | Y11: =IFERROR(DATEDIF(S11,TODAY(),"Y"),"NA") -> 5 | Z11: NA | AA11: WALTER OLIVA | AB11: NA | AC11: ANALISTA CONTABLE
B12: 90 | C12: NA | D12: LAPTOP | E12: CTL2020-017 | F12: HOLDING.COM | G12: PRINCIPAL | H12: LENOVO | I12: L590 | J12: PF2D01KZ | K12: INTEL CORE I7 8 GEN | L12: INTEL(R) CORE(TM) I7-8565U CPU @ 1.80GHZ (2001 MHZ) | M12: 500 GB (SSD) | N12: 16 GB | O12: ADLX65YCC2D | P12: 002B67AD50FA | Q12: F8AC65F9E714 | R12: NA | S12: 44105 | T12: 45200 | U12: =IFERROR(DATEDIF(TODAY(),T12,"D"),0) -> 0 | V12: =IF(U12=0,"SIN GARANTIA","CON GARANTIA") -> SIN GARANTIA | W12: OPERATIVO | X12: FAFF01-00002241 | Y12: =IFERROR(DATEDIF(S12,TODAY(),"Y"),"NA") -> 5 | Z12: NA | AA12: LUIS SOLORZANO | AB12: NA | AC12: ASISTENTE DE PROYECTOS
B13: 15 | C13: NA | D13: LAPTOP | E13: DESKTOP-USI46Q4 | F13: HOLDING.COM | G13: PRINCIPAL | H13: HP | I13: PROBOOK 450 G2 | J13: CND5217T96 | K13: INTEL CORE I5 4 GEN | L13: INTEL(R) CORE(TM) I5-4210U CPU @ 1.70GHZ (1992 MHZ) | M13: 1 TB (HDD) | N13: 16 GB | O13: HP PPP009C | P13: 308D9967D6C0 | Q13: D85DE2390A31 | R13: NA | S13: 42156 | T13: 42556 | U13: =IFERROR(DATEDIF(TODAY(),T13,"D"),0) -> 0 | V13: =IF(U13=0,"SIN GARANTIA","CON GARANTIA") -> SIN GARANTIA | W13: INOPERATIVO | X13: NA | Y13: =IFERROR(DATEDIF(S13,TODAY(),"Y"),"NA") -> 10 | Z13: NA | AA13: RODOLFO DÍAZ | AB13: S | AC13: SUPERVISOR DE SEGURIDAD | AE13: PENDIENTE DE ENVIAR DE PATIVILCA A FECHA 16/03/2021
C14: NA | D14: MOUSE | H14: LOGITECH | I14: M185 | J14: 1552LZ0H4UF8 | U14: =IFERROR(DATEDIF(TODAY(),T14,"D"),0) -> 0 | V14: =IF(U14=0,"SIN GARANTIA","CON GARANTIA") -> SIN GARANTIA | W14: INOPERATIVO | AE14: MOUSE NO TIENE CONECTOR USB
U15: =IFERROR(DATEDIF(TODAY(),T15,"D"),0) -> 0 | V15: =IF(U15=0,"SIN GARANTIA","CON GARANTIA") -> SIN GARANTIA | X15: =IFERROR(DATEDIF(R15,TODAY(),"Y"),"NA") -> 125 | Y15: =IFERROR(DATEDIF(S15,TODAY(),"Y"),"NA") -> 125
U16: =IFERROR(DATEDIF(TODAY(),T16,"D"),0) -> 0 | V16: =IF(U16=0,"SIN GARANTIA","CON GARANTIA") -> SIN GARANTIA | X16: =IFERROR(DATEDIF(R16,TODAY(),"Y"),"NA") -> 125 | Y16: =IFERROR(DATEDIF(S16,TODAY(),"Y"),"NA") -> 125
U17: =IFERROR(DATEDIF(TODAY(),T17,"D"),0) -> 0 | V17: =IF(U17=0,"SIN GARANTIA","CON GARANTIA") -> SIN GARANTIA | X17: =IFERROR(DATEDIF(R17,TODAY(),"Y"),"NA") -> 125 | Y17: =IFERROR(DATEDIF(S17,TODAY(),"Y"),"NA") -> 125
U18: =IFERROR(DATEDIF(TODAY(),T18,"D"),0) -> 0 | V18: =IF(U18=0,"SIN GARANTIA","CON GARANTIA") -> SIN GARANTIA | X18: =IFERROR(DATEDIF(R18,TODAY(),"Y"),"NA") -> 125 | Y18: =IFERROR(DATEDIF(S18,TODAY(),"Y"),"NA") -> 125
U19: =IFERROR(DATEDIF(TODAY(),T19,"D"),0) -> 0 | V19: =IF(U19=0,"SIN GARANTIA","CON GARANTIA") -> SIN GARANTIA | X19: =IFERROR(DATEDIF(R19,TODAY(),"Y"),"NA") -> 125 | Y19: =IFERROR(DATEDIF(S19,TODAY(),"Y"),"NA") -> 125
U20: =IFERROR(DATEDIF(TODAY(),T20,"D"),0) -> 0 | V20: =IF(U20=0,"SIN GARANTIA","CON GARANTIA") -> SIN GARANTIA | X20: =IFERROR(DATEDIF(R20,TODAY(),"Y"),"NA") -> 125 | Y20: =IFERROR(DATEDIF(S20,TODAY(),"Y"),"NA") -> 125

Sheet BD Accesorios
D2: Registro de Accesorios
B4: 1 | C4: 2 | D4: 3 | E4: 4 | F4: 5 | G4: 6 | H4: 7 | I4: 8 | J4: 9 | K4: 10 | L4: 11 | M4: 12 | N4: 13 | O4: 14 | P4: 15 | Q4: 16 | R4: 17 | T4: 18
B5: DATA | C5: DATOS DEL EQUIPO INFORMÁTICO | K5: DATOS DE UBICACIÓN DEL EQUIPO | Q5: COMPLEMENTARIOS
B6: ITEM | C6: FE_REGISTRO | D6: DESCRIPCIÓN | E6: MARCA | F6: MODELO | G6: SERIE | H6: CATEGORÍA | I6: TIPO | J6: DIRECCIÓN IP | K6: SEDE | L6: UBICACIÓN | M6: DEPARTAMENTO | N6: PROVINCIA | O6: DISTRITO | P6: DIRECCION | Q6: PROVEEDOR | R6: FE_MOD_REG | S6: ESTADO | T6: COMENTARIOS
B7: 1 | D7: MOUSE | E7: LOGITECH | F7: M185 | G7: 1552LZ0H4UF8 | K7: SAUCES | M7: LIMA | N7: LIMA | O7: ATE | P7: AV. SANTA CECILIA NRO. 575 | S7: INOPERATIVO
B8: 2 | D8: ANEXO | E8: GRANDSTREAM | F8: GXP1630 | G8: 20EZ0XUJ20D2B00F | K8: SAUCES | L8: JEFE LOGISTICA | M8: LIMA | N8: LIMA | O8: ATE | P8: AV. SANTA CECILIA NRO. 575 | S8: OPERATIVO | T8: 222
B9: 3 | D9: ANEXO | E9: GRANDSTREAM | F9: GXP2130 | G9: 20EYZK0J70E268E3 | K9: SAUCES | L9: GERENTE COMERCIAL | M9: LIMA | N9: LIMA | O9: ATE | P9: AV. SANTA CECILIA NRO. 575 | S9: OPERATIVO | T9: 227
B10: 4 | D10: ANEXO | E10: GRANDSTREAM | F10: GXP1628 | G10: 22MT9YDHA0C42DA7 | K10: SAUCES | L10: AREA TRAFICO | M10: LIMA | N10: LIMA | O10: ATE | P10: AV. SANTA CECILIA NRO. 575 | S10: OPERATIVO | T10: 215
B11: 5
B12: 6
B13: 7
B14: 8
B15: 9
B16: 10
B17: 11
B18: 12
B19: 13
B20: 14
B21: 15
B22: 16
... B34: 28
